Workbook

Sheet Credit (3)
C6: မတည်ငွေ | E6: =+Statment!D5 -> 1500000
C8: ကုန်ကြွေးရငွေ | E8: =Statment!F15 -> 0
C9: ငွေသားရောင်းရငွေ | E9: =Statment!F14 -> 2103800
C10: ငွေသားရင်းနှီးမြုပ်နှံမှု
C11: လအတွင်းရငွေ | E11: =E8+E9+E10 -> 2103800
C12: ကုန်ဝယ် | E12: ='Yogut Profit'!M104 -> 1304600
C13: အထွေထွေအသုံးစရိတ် | E13: ='Other Expen '!E28 -> 689500
C14: နေ့စဉ်အသုံးစရိတ် | E14: ='daily expen'!C63 -> 350500
C15: လအတွင်းသုံးစွဲငွေ | E15: =E12+E13+E14 -> 2344600
C18: ငွေသားလက်ကျန်ငွေစုစုပေါင်း | E18: =E11-E15 -> -240800

Sheet Credit 
B1: ကုန်ကြွေးရငွေ
A3: Date | B3: အကြောင်းအရာ | C3: ရငွေ
A4: ၅-၇-၂၀၂၆ | B4: မေတ္တာစံ | C4: =36000+33000 -> 69000
A5: ၆-၇-၂၀၂၆ | B5: အားကစား
B20: စုစုပေါင်း | C20: =SUM(C4:C19) -> 69000

Sheet Statment
B5: မတည်ငွေ | D5: =SUM(D6:D13) -> 1500000
B6: ရေခဲသေတ္တာ | D6: 900000
B7: တံဆိပ်ဒီဇိုင်း | D7: =85000+25000 -> 110000
B8: ဒန်အိုး | D8: 200000
B9: လိပ်စာကဒ် | D9: 15000
B10: Date Stant | D10: 85000
B11: အွန်လိုင်းလိုင်စင် | D11: 120000
B12: ဓါတ်ခွဲခ | D12: 70000
B14: လအတွင်း ရငွေ | F14: =D15+D17+D18 -> 2103800
B15: ကုန်ကြွေးရငွေ | D15: ='Credit '!C20 -> 69000
B16: ငွေသားရင်းနှီးမြုပ်နှံမှု
B17: ရရန်ကုန်ကြွေး | D17: ='Yogut Profit'!U104 -> 124000
B18: ငွေသားရောင်းရငွေ | D18: ='Yogut Profit'!V104 -> 1910800 | F18: ='Yogut Profit'!FV104 -> 0
B20: လအတွင်း သုံးစွဲငွေ | D20: =D21+D22+D23 -> 1994100
B21: ကုန်ဝယ် | D21: ='Yogut Profit'!M104 -> 1304600
B22: အခြားအသုံးစရိတ် | D22: ='Other Expen '!E28 -> 689500
B23: နေ့စဉ်အသုံးစရိတ်
J25: ၐ
B26: ကုန်ပစ္စည်းလက်ကျန်တန်ဖိုး | D26: =+'Yogut Profit'!Y109 -> 589350 | F26: =+'Yogut Profit'!Y109 -> 589350
B27: စာရင်းညှိနှိုင်းချက် | D27: =D20+D26 -> 2583450 | F27: =F14+F26 -> 2693150
B29: အသားတင်အမြတ် | F29: =F27-D27 -> 109700

Sheet Profit
B5: တစ်နှစ် ဝင်ငွေ/ လည်ပတ်ငွေ | E5: 26500000
B7: ကုန်ကြမ်း | C7: Viss | D7: Rate | E7: Value
B8: နွားနို့ | C8: 2150 | D8: 5000 | E8: =C8*D8 -> 10750000
B9: သကြား | C9: =C8*0.15 -> 322.5 | D9: 4800 | E9: =C9*D9 -> 1548000
B10: မီး | C10: ၁၂ လ | D10: 15000 | E10: =12*25000 -> 300000
B11: လုပ်သား | C11: ၅ ဦး | D11: 100000 | E11: =D11*5*12 -> 6000000
B12: အထွေထွေအသုံးစရိတ် | C12: ၁၂ လ | D12: 300000 | E12: =300000*12 -> 3600000
B14: စုစုပေါင်း | E14: =SUM(E8:E12) -> 22198000
B15: အသားတင်အမြတ် | E15: =E5-E14 -> 4302000
B17: ကုန်ချောထုတ်လုပ်မှု | C17: အရေအတွက် | D17: Rate | E17: Value
B18: ၂၅၀ ML | C18: 12850 | D18: 1800 | E18: =C18*D18 -> 23130000
B19: 1 Litter | C19: 520 | D19: 6500 | E19: =C19*D19 -> 3380000
E21: =E18+E19 -> 26510000
F23: +

Sheet Statment (2)
B2: စာရင်းညှိနှိုင်းချက်
B3: အကြောင်းအရာ | C3: သင့်ငွေ | E3: အကြောင်းအရာ | F3: သင့်ငွေ
B4: မတည်ငွေ | C4: =Statment!D5 -> 1500000 | E4: မတည်ငွေ | F4: =Statment!D5 -> 1500000
B5: လအတွင်း သုံးစွဲငွေ | C5: =Statment!D20 -> 1994100 | E5: ငွေသားရငွေ | F5: =Statment!F14 -> 2103800
B6: လက်ကျန်တန်ဖိုး | C6: =Statment!D26 -> 589350 | E6: လက်ကျန်တန်ဖိုး | F6: =Statment!F26 -> 589350
B7: အသားတင်အမြတ် | C7: =Statment!F29 -> 109700 | E7: ရရန်ကုန်ကြွေး
B16: စုစုပေါင်း | C16: =SUM(C4:C15) -> 4193150 | E16: စုစုပေါင်း | F16: =SUM(F4:F15) -> 4193150
F18: =F16-C16 -> 0

Sheet Statment (3)
B2: အငဲလေးစားသောက်ကုန်လုပ်ငန်း
A3: စဉ် | B3: အမျိုးအမည် | C3: ဝင်ဆံ့မှု | D3: ငွေ (ကျပ်) | E3: မှတ်ချက်
A4: 1 | B4: အငဲလေး သဘာဝဒိန်ချဉ်(သကြား) | C4: 250 Ml | D4: 1800
A5: 2 | B5: အငဲလေး သဘာဝဒိန်ချဉ်(ထန်းလျက်) | C5: 250 Ml | D5: 1800
A6: 3 | B6: အငဲလေး သဘာဝဒိန်ချဉ်(သကြား) | C6: 1 litter | D6: 6500
A7: 4 | B7: အငဲလေး သဘာဝဒိန်ချဉ်(ထန်းလျက်) | C7: 1 litter | D7: 6500
A8: 5 | B8: အငဲလေး မလှိုင်ပြည့်သဘာဝနွားနို့ | C8: 250 Ml | D8: 1800
A9: 6 | B9: အငဲလေး မလှိုင်ပြည့်သဘာဝနွားနို့ | C9: 1 litter | D9: 6500
A10: 7 | B10: အငဲလေး ကျန်းမာရေးချိယားစေ့ ဒိန်ချဉ် | C10: 250 Ml | D10: 2100 | E10: ၁-၃-၂၀၂၆ရက်နေ့မှစတင်
A11: 8 | B11: အငဲလေး ကျန်းမာရေးချိယားစေ့ ဒိန်ချဉ် | C11: 1 litter | D11: 8000 | E11: ဖြန့်ဖြူးရောင်းချပါမည်

Sheet Other Expen 
A1: အခြားအသုံးစရိတ်များ
A2: Date | B2: အကြောင်းအရာ | C2: Viss | D2: rate | E2: သင့်ငွေ | F2: သကြား | G2: ဆီဇိုး | H2: မီးသွေး | J2: အခြား
A3: ၁-၉-၂၀၂၆ | B3: chia Seed | C3: 4 | D3: 48000 | E3: =C3*D3 -> 192000
B4: Transport Charge | E4: 9000
A5: ၂-၉-၂၀၂၆ | B5: သကြား | C5: 5 | D5: 4500 | E5: =C5*D5 -> 22500
B6: မီးသွေး | C6: 5 | D6: 1000 | E6: =C6*D6 -> 5000
B7: ဆိုင်ကယ်ဆီဖိုး | E7: 10000
A8: ၃-၉-၂၀၂၆ | B8: သကြား | C8: 4 | D8: 4500 | E8: =C8*D8 -> 18000
A9: ၄-၉-၂၀၂၆ | B9: မီးသွေး | C9: 5 | D9: 1000 | E9: =C9*D9 -> 5000
A10: ၅-၉-၂၀၂၆ | B10: ဆီဖိုး | E10: 50000
A11: ၆-၉-၂၀၂၆ | B11: သကြား | C11: 4 | D11: 4500 | E11: =C11*D11 -> 18000
A12: ၇-၉-၂၀၂၆ | B12: ဆီဖိုး | E12: 100000
A13: ၁၀-၉-၂၀၂၆ | B13: သကြား | C13: 5 | D13: 4500 | E13: =C13*D13 -> 22500
B14: မီးသွေး | C14: 5 | D14: 1000 | E14: =C14*D14 -> 5000
A15: ၁၂-၉-၂၀၂၆ | B15: သကြား | C15: 10 | D15: 4500 | E15: =C15*D15 -> 45000
B16: အိတ် | E16: 12500
A17: ၁၃-၉-၂၀၂၆ | B17: ဆိုင်ကယ်ဆီဖိုး | E17: 20000
B18: ကားဆီဖိူး | E18: 150000
A19: ၁၄-၉-၂၀၂၆ | B19: မီးသွေး | C19: 5 | D19: 1000 | E19: =C19*D19 -> 5000
B28: စုစုပေါင်း | E28: =SUM(E3:E27) -> 689500

Sheet Yogut Profit
A3: ကုန်ဝယ် | O3: ကုန်ရောင်း
A4: Date | B4: ဘူးခွံ | F4: တံဆိပ် | J4: နွားနို့ | M4: သင့်ငွေ | O4: Date | P4: ဝယ်သူ | Q4: ရေအတွက် | S4: Rate | T4: လတွင်း | U4: ကုန်ကြွေး | V4: လက်ငင်း | W4: ကုန်ကြွေး | X4: ရရန် | Y4: မှတ်ချက်
B5: 250 ml | C5: 1 liter | D5: Rate | E5: Total | F5: 250 ml | G5: 1 liter | H5: Rate | I5: Total | J5: Viss | K5: Rate | L5: Total | Q5: 250 ml | R5: 1 liter | T5: ရောင်းရငွေ | V5: ရောင်းရငွေ | W5: ရငွေ | X5: ကုန်ကြွေး
A6: ၁-၉-၂၀၂၆ | J6: 30 | K6: 5500 | L6: =J6*K6 -> 165000 | M6: =+L6 -> 165000 | O6: ၁-၉-၂၀၂၆ | P6: DRD သက်သာ | Q6: 5 | S6: 2000 | T6: =Q6*S6 -> 10000
Q7: 5 | S7: 2400 | T7: =Q7*S7 -> 12000 | X7: =+U7 -> 0
P8: စာရင်းစစ်ချုပ် | Q8: 10 | S8: 2000 | T8: =Q8*S8 -> 20000
Q9: 10 | S9: 2400 | T9: =Q9*S9 -> 24000
A10: ၂-၉-၂၀၂၆ | J10: 30 | K10: 5500 | L10: =J10*K10 -> 165000 | M10: =+L10 -> 165000 | O10: ၂-၉-၂၀၂၆ | P10: Moe Thiri | Q10: 15 | S10: 2000 | T10: =Q10*S10 -> 30000 | X10: =+U10 -> 0
Q11: 15 | S11: 2400 | T11: =Q11*S11 -> 36000 | X11: =+U11 -> 0
P12: ABC mark | Q12: 20 | S12: 2000 | T12: =Q12*S12 -> 40000
P13: Academia | Q13: 30 | S13: 2000 | T13: =Q13*S13 -> 60000
Q14: 15 | S14: 2400 | T14: =Q14*S14 -> 36000
P15: နို့စိမ်း | T15: 28000
O16: ၃-၉-၂၀၂၆ | P16: မေတ္တာစံ | Q16: 20 | S16: 2000 | T16: =Q16*S16 -> 40000 | X16: =+U16 -> 0
P17: GTI အင်ကြင်း | Q17: 10 | S17: 2400 | T17: =Q17*S17 -> 24000
Q18: 10 | S18: 2000 | T18: =Q18*S18 -> 20000
Q19: 5 | S19: 2000 | T19: =Q19*S19 -> 10000
P20: MCRD | Q20: 20 | S20: 2000 | T20: =Q20*S20 -> 40000
P21: DRD သက်သာ | Q21: 5 | S21: 2000 | T21: =Q21*S21 -> 10000
Q22: 15 | S22: 2400 | T22: =Q22*S22 -> 36000
A23: ၄-၉-၂၀၂၆ | J23: 34 | K23: 5500 | L23: =J23*K23 -> 187000 | M23: =+L23 -> 187000 | O23: ၄-၉-၂၀၂၆ | P23: ရတနာမွန် | Q23: 15 | S23: 2000 | T23: =Q23*S23 -> 30000
Q24: 15 | S24: 2400 | T24: =Q24*S24 -> 36000
P25: CaCa Co | Q25: 30 | S25: 2400 | T25: =Q25*S25 -> 72000
P26: နို့စိမ်း | T26: 8000
O27: ၆-၉-၂၀၂၆ | P27: Academia | Q27: 25 | S27: 2000 | T27: =Q27*S27 -> 50000
Q28: 10 | S28: 2400 | T28: =Q28*S28 -> 24000
P29: အိမ်ရောင်း | Q29: 5 | S29: 2200 | T29: =Q29*S29 -> 11000
P30: ရုံး-၃ | Q30: 12 | S30: 2400 | T30: =Q30*S30 -> 28800
A31: ၇-၉-၂၀၂၆ | J31: 32 | K31: 5500 | L31: =J31*K31 -> 176000 | M31: =+L31 -> 176000 | O31: ၇-၉-၂၀၂၆ | P31: မေတ္တာစံ | Q31: 10 | S31: 2400 | T31: =Q31*S31 -> 24000 | U31: 24000 | X31: =+U31 -> 24000
P32: မူဆယ် | Q32: 15 | S32: 2000 | T32: =Q32*S32 -> 30000 | X32: =+U32 -> 0
Q33: 15 | S33: 2400 | T33: =Q33*S33 -> 36000 | X33: =+U33 -> 0
P34: DRD သက်သာ | Q34: 10 | S34: 2000 | T34: =Q34*S34 -> 20000 | X34: =+U34 -> 0
Q35: 10 | S35: 2400 | T35: =Q35*S35 -> 24000 | X35: =+U35 -> 0
P36: MCRD | Q36: 15 | S36: 2000 | T36: =Q36*S36 -> 30000 | X36: =+U36 -> 0
P37: သာသနာရေး | Q37: 10 | S37: 2000 | T37: =Q37*S37 -> 20000 | X37: =+U37 -> 0
P38: အားကာ | Q38: 20 | S38: 2000 | T38: =Q38*S38 -> 40000 | X38: =+U38 -> 0
P39: ပညလက | Q39: 10 | S39: 2000 | T39: =Q39*S39 -> 20000 | X39: =+U39 -> 0
P40: နို့စိမ်း | T40: 20000 | X40: =+U40 -> 0
O41: ၈-၉-၂၀၂၆ | P41: DRD သက်သာ | Q41: 10 | S41: 2400 | T41: =Q41*S41 -> 24000 | X41: =+U41 -> 0
O42: ၉-၉-၂၀၂၆ | P42: ချယ်ရီဈေး | Q42: 5 | S42: 2000 | T42: =Q42*S42 -> 10000 | X42: =+U42 -> 0
...

Sheet daily expen
A1: နေ့စဉ်အသုံးစရိတ်
A2: Date | B2: အကြောင်းအရာ | C2: သင့်ငွေ
A3: ၁-၉-၂၀၂၆ | B3: အငဲသွားတိုက်တံ | C3: 3500
B4: ခေါက်ဆွဲ ကြော် လက်ဖက်ရည်ထုတ် | C4: 7500
A5: ၂-၉-၂၀၂၆ | B5: ငပိကြော် | C5: 8000
B6: ဆိုင်ထိုင် | C6: 9700
A7: ၃-၉-၂၀၂၆ | B7: ဝက်အူချောင်း | C7: 19000
B8: ဆန် | C8: 41000
A9: ၄-၉-၂၀၂၆ | B9: ဆေးလိပ်+သောက်စရာ | C9: 12500
A10: ၅-၉-၂၀၂၆ | B10: ရေသန့် | C10: 2000
A11: ၆-၉-၂၀၂၆ | B11: G-12 Match | C11: 12000
A12: ၇-၉-၂၀၂၆ | B12: ကွမ်း | C12: 2000
A13: ၈-၉-၂၀၂၆ | B13: ဝက်သား | C13: 25000
A14: ၉-၉-၂၀၂၆ | B14: ခေါက်ဆွဲ+နံနံပင်ရှောက်ရွက် | C14: 3000
A15: ၁၀-၉-၂၀၂၆ | B15: အတိုး | C15: 15000
A16: ၁၁-၉-၂၀၂၆ | B16: အမဲစွပ် | C16: 9000
A17: ၁၂-၉-၂၀၂၆ | B17: ဆေးဝယ် | C17: 28500
A18: ၁၃-၉-၂၀၂၆ | B18: ငဲငဲမုန့်ဖိုး | C18: 9000
B19: သားကြီးဖိနပ် | C19: 60000
B20: သားကြီးမုန့် | C20: 30000
B21: ချောကလက် | C21: 17000
B22: ငဲငဲ Project စာအုပ် | C22: 25000
A23: ၁၄-၉-၂၀၂၆ | B23: သောက်စရာ | C23: 6500
A24: ၁၅-၉-၂၀၂၆ | B24: ပဲနို့ | C24: 5300
B63: စုစုပေါင်းအသုံး | C63: =SUM(C3:C62) -> 350500

Sheet Yogurt
A1: အငဲလေး
A2: ဒိန်ချဉ်
B3: Ph 09453932632-09428319270 | E3: Date8 -9-2026
A4: စဉ် | B4: အမျိုးအစား | C4: အရေအတွက် | D4: နှုန်း
A5: 1 | B5: Chia Seed Yoghurt | C5: 10 | D5: 2400 | E5: =C5*D5 -> 24000
D12: Total | E12: =SUM(E5:E11) -> 24000
A15: အငဲလေး
A16: ဒိန်ချဉ်
B17: Ph 09453932632-09428319270 | E17: Date -6-2026
A18: စဉ် | B18: အမျိုးအစား | C18: အရေအတွက် | D18: နှုန်း | E18: သင့်ငွေ
A19: 1 | B19: Milk Yogut | E19: =C1 -> 0
D26: Total | E26: =E19 -> 0

Sheet Date
A2: 25-1-2026 | B2: 25-1-2026 | C2: 25-1-2026 | D2: 25-1-2026 | E2: 25-1-2026 | F2: 25-1-2026 | G2: 25-1-2026
A3: 25-1-2026 | B3: 25-1-2026 | C3: 25-1-2026 | D3: 25-1-2026 | E3: 25-1-2026 | F3: 25-1-2026 | G3: 25-1-2026
A4: 25-1-2026 | B4: 25-1-2026 | C4: 25-1-2026 | D4: 25-1-2026 | E4: 25-1-2026 | F4: 25-1-2026 | G4: 25-1-2026
A5: 25-1-2026 | B5: 25-1-2026 | C5: 25-1-2026 | D5: 25-1-2026 | E5: 25-1-2026 | F5: 25-1-2026 | G5: 25-1-2026
A6: 25-1-2026 | B6: 25-1-2026 | C6: 25-1-2026 | D6: 25-1-2026 | E6: 25-1-2026 | F6: 25-1-2026 | G6: 25-1-2026
A7: 25-1-2026 | B7: 25-1-2026 | C7: 25-1-2026 | D7: 25-1-2026 | E7: 25-1-2026 | F7: 25-1-2026 | G7: 25-1-2026
A8: 25-1-2026 | B8: 25-1-2026 | C8: 25-1-2026 | D8: 25-1-2026 | E8: 25-1-2026 | F8: 25-1-2026 | G8: 25-1-2026
A9: 25-1-2026 | B9: 25-1-2026 | C9: 25-1-2026 | D9: 25-1-2026 | E9: 25-1-2026 | F9: 25-1-2026 | G9: 25-1-2026
A10: 25-1-2026 | B10: 25-1-2026 | C10: 25-1-2026 | D10: 25-1-2026 | E10: 25-1-2026 | F10: 25-1-2026 | G10: 25-1-2026
A11: 25-1-2026 | B11: 25-1-2026 | C11: 25-1-2026 | D11: 25-1-2026 | E11: 25-1-2026 | F11: 25-1-2026 | G11: 25-1-2026
A12: 25-1-2026 | B12: 25-1-2026 | C12: 25-1-2026 | D12: 25-1-2026 | E12: 25-1-2026 | F12: 25-1-2026 | G12: 25-1-2026
A13: 25-1-2026 | B13: 25-1-2026 | C13: 25-1-2026 | D13: 25-1-2026 | E13: 25-1-2026 | F13: 25-1-2026 | G13: 25-1-2026
... A41: 25-1-2026 | B41: 25-1-2026 | C41: 25-1-2026 | D41: 25-1-2026 | E41: 25-1-2026 | F41: 25-1-2026 | G41: 25-1-2026

Sheet Canddle
A1: စန်းပွင့်
A2: ဖယောင်းတိုင်
B3: Ph 09453932632-09428319270 | E3: Date 5-1-2026 | K3: ပြောင်း | L3: ဝက်ခေါက်
A4: စဉ် | B4: အမျိုးအစား | C4: အရေအတွက် | D4: နှုန်း | J4: အက်စတာ | K4: 1 | L4: 1
A5: 1 | B5: အဖြူသေး ၂၄တိုင် | C5: 15 | D5: 1300 | E5: =C5*D5 -> 19500 | J5: စိမ်း
A6: 2 | B6: အဝါသေး ၂၄တိုင် | C6: 10 | D6: 1300 | E6: =C6*D6 -> 13000 | J6: ဇင်ထက် | K6: 4
A7: 3 | B7: အနီသေး ၂၄ တိုင် | C7: 15 | D7: 1300 | E7: =C7*D7 -> 19500
A8: 4 | B8: ရောင်စုံ သေး ၂၄ တိုင် | C8: 15 | D8: 1300 | E8: =C8*D8 -> 19500
B12: Total | C12: =SUM(C5:C11) -> 55 | D12: 1300 | E12: =SUM(E5:E11) -> 71500
A15: အငဲလေး
A16: မလိုင်အပြည့် သဘာဝနွားနို့
B17: Ph 09453932632-09428319270 | E17: Date -1-2026
A18: စဉ် | B18: အမျိုးအစား | C18: အရေအတွက် | D18: နှုန်း | E18: သင့်ငွေ
A19: 1
D26: Total | E26: =E19 -> 0

Sheet Price
A1: 2000 | B1: 2000 | C1: 2000 | D1: 2000 | E1: 2000 | F1: 2000 | G1: 2000 | H1: 2000 | I1: 2000
A2: 2000 | B2: 2000 | C2: 2000 | D2: 2000 | E2: 2000 | F2: 2000 | G2: 2000 | H2: 2000 | I2: 2000
A3: 2000 | B3: 2000 | C3: 2000 | D3: 2000 | E3: 2000 | F3: 2000 | G3: 2000 | H3: 2000 | I3: 2000
A4: 2000 | B4: 2000 | C4: 2000 | D4: 2000 | E4: 2000 | F4: 2000 | G4: 2000 | H4: 2000 | I4: 2000
A5: 2000 | B5: 2000 | C5: 2000 | D5: 2000 | E5: 2000 | F5: 2000 | G5: 2000 | H5: 2000 | I5: 2000
A6: 2000 | B6: 2000 | C6: 2000 | D6: 2000 | E6: 2000 | F6: 2000 | G6: 2000 | H6: 2000 | I6: 2000
A7: 2000 | B7: 2000 | C7: 2000 | D7: 2000 | E7: 2000 | F7: 2000 | G7: 2000 | H7: 2000 | I7: 2000
A8: 2000 | B8: 2000 | C8: 2000 | D8: 2000 | E8: 2000 | F8: 2000 | G8: 2000 | H8: 2000 | I8: 2000
A9: 2000 | B9: 2000 | C9: 2000 | D9: 2000 | E9: 2000 | F9: 2000 | G9: 2000 | H9: 2000 | I9: 2000
A10: 2000 | B10: 2000 | C10: 2000 | D10: 2000 | E10: 2000 | F10: 2000 | G10: 2000 | H10: 2000 | I10: 2000
A11: 2000 | B11: 2000 | C11: 2000 | D11: 2000 | E11: 2000 | F11: 2000 | G11: 2000 | H11: 2000 | I11: 2000
A12: 2000 | B12: 2000 | C12: 2000 | D12: 2000 | E12: 2000 | F12: 2000 | G12: 2000 | H12: 2000 | I12: 2000
... A27: 2000 | B27: 2000 | C27: 2000 | D27: 2000 | E27: 2000 | F27: 2000 | G27: 2000 | H27: 2000 | I27: 2000
